Workbook

Sheet シート10
A1: total distance (carry + roll)
B2: Novice with bad clubs | C2: Novice | D2: Amateur golfer | E2: Pro Golfer | F2: Pro Golfer | G2: Super Pro Golfer
B3: COMMON | C3: UNCOMMON | D3: RARE | E3: MYTHIC | F3: LEGEND | G3: SUPREME
A4: Driver | B4: 174 | C4: 205 | D4: 230 | E4: 270 | F4: 320 | G4: 350
A5: 3-Wood | B5: =C5-25 -> 145 | C5: =D5-40 -> 170 | D5: =E5-40 -> 210 | E5: 250 | F5: =E5+30 -> 280 | G5: =F5+30 -> 310
A6: 5-Wood | B6: =C6-25 -> 130 | C6: =D6-40 -> 155 | D6: =E6-40 -> 195 | E6: 235 | F6: =E6+30 -> 265 | G6: =F6+30 -> 295
A7: 7-Wood | B7: =C7-25 -> 115 | C7: =D7-40 -> 140 | D7: =E7-40 -> 180 | E7: 220 | F7: =E7+30 -> 250 | G7: =F7+30 -> 280
A8: 3-Iron | B8: =C8-25 -> 105 | C8: =D8-40 -> 130 | D8: =E8-40 -> 170 | E8: 210 | F8: =E8+30 -> 240 | G8: =F8+30 -> 270
A9: 4-Iron | B9: =C9-25 -> 95 | C9: =D9-40 -> 120 | D9: =E9-40 -> 160 | E9: 200 | F9: =E9+30 -> 230 | G9: =F9+30 -> 260
A10: 5-Iron | B10: =C10-25 -> 85 | C10: =D10-40 -> 110 | D10: =E10-40 -> 150 | E10: 190 | F10: =E10+30 -> 220 | G10: =F10+30 -> 250
A11: 6-Iron | B11: =C11-25 -> 75 | C11: =D11-40 -> 100 | D11: =E11-40 -> 140 | E11: 180 | F11: =E11+30 -> 210 | G11: =F11+30 -> 240
A12: 7-Iron | B12: =C12-25 -> 65 | C12: =D12-40 -> 90 | D12: =E12-40 -> 130 | E12: 170 | F12: =E12+30 -> 200 | G12: =F12+30 -> 230
A13: 8-Iron | B13: =C13-25 -> 55 | C13: =D13-40 -> 80 | D13: =E13-40 -> 120 | E13: 160 | F13: =E13+30 -> 190 | G13: =F13+30 -> 220
A14: 9-Iron | B14: =C14-25 -> 45 | C14: =D14-40 -> 70 | D14: =E14-40 -> 110 | E14: 150 | F14: =E14+30 -> 180 | G14: =F14+30 -> 210
A15: Pitching Wedge | B15: 40 | C15: =D15-40 -> 60 | D15: =E15-40 -> 100 | E15: 140 | F15: =E15+30 -> 170 | G15: =F15+30 -> 200
A16: Approach Wedge | B16: 35 | C16: =D16-40 -> 50 | D16: =E16-40 -> 90 | E16: 130 | F16: =E16+30 -> 160 | G16: =F16+30 -> 190 | H16: PWedge -> AWedge->SWedge
A17: Sand Wedge | B17: 30 | C17: =D17-40 -> 30 | D17: =E17-40 -> 70 | E17: 110 | F17: =E17+30 -> 140 | G17: =F17+30 -> 170

Sheet CALCULATOR
H2: . | K2: Randomizer | L2: =RANDBETWEEN(1,3) -> 1 | M2: Mechanical Misake | N2: 0 | X2: CHARCTER | AA2: UPGRADES
L3: Bunker | M3: SemiRough | U3: ROLL AFTER COEFFICIENT
F4: UPGRADES | L4: =VLOOKUP(L3,RECOVERY!$AA$8:$AP$10,2,FALSE) -> 2.5 | M4: =VLOOKUP(M3,RECOVERY!$AA$27:$AP$29,2,FALSE) -> 0.65 | N4: -1.5 | O4: 0 | P4: 1.5 | R4: 1/-1 | T4: 0.1 | U4: 1.33 | V4: -1.23
B5: COMMON | D5: Base Parameter | E5: Parameter | F5: =SUM(F6:F11)&"/24" -> 34/24 | G5: Base Rar Dist | H5: SHOT DISTANCE | I5: ACC. Coeff | J5: Shot Power Multiplyer | K5: ACC. DEVIATION | L5: REC. FOR ACC | M5: REC. FOR POWER | N5: TOP SPIN | O5: NO SPIN | P5: BACK SPIN | Q5: Deviation | R5: SIDE SPIN POWER | S5: Calculated Spin | T5: DEFAULT | U5: TOP SPIN | V5: BACK SPIN | X5: COMMON | Y5: Base Parameter | Z5: Parameter | AA5: =SUM(AA6:AA9)&"/25" -> 0/25 | AB5: Base Rar Dist
B6: Driver | C6: Power | D6: 150 | E6: =D6+F6 -> 184 | F6: 34 | G6: 35 | H6: =$G$6+(E6/2)+$AB$6+(Z6/2)+$L$2 -> 173 | I6: =1-(E7/1000) -> 0.87 | J6: =ROUND(POWER(E6/100,0.5),3) -> 1.356 | K6: =(G8*J6*I6*N2) -> 0 | L6: =1+(L4-1)*(1-E10/500) -> 2.485 | M6: =M4+((1-M4)*0.5*E10/400) -> 0.6521875 | N6: =(E9+(Q6*N4))/1.3 -> 26.230769 | O6: =(D9+(P6*O4))/1.3 -> 26.923077 | P6: =(E9+(Q6*P4))/1.3 -> 27.615385 | Q6: =3*(E8/100) -> 0.6 | R6: =E8*1*(VLOOKUP(B6,SPIN!$M$27:$N$40,2,FALSE)) -> 800 | S6: =E8*2*3.14/60 -> 2.0933333 | T6: =$S6*T4*8 -> 1.6746667 | U6: =$S6*U4*8 -> 22.273067 | V6: =$S6*V4*8 -> -20.5984 | X6: STRENGTH | Y6: 30 | Z6: =Y6+AA6 -> 30 | AB6: 30
C7: Accuracy | D7: 130 | E7: =D7+F7 -> 130 | G7: Mistake based on Rarity | H7: . | X7: CLUB CONTROL | Y7: 50 | Z7: =Y7+AA7 -> 50
C8: Spin | D8: 20 | E8: =D8+F8 -> 20 | G8: 20 | X8: STAMINA | Y8: 150 | Z8: =Y8+AA8 -> 150
C9: Loft | D9: 35 | E9: =D9+F9 -> 35 | X9: STAMINA REG | Y9: 5 | Z9: =Y9+AA9 -> 5
C10: Recovery | D10: 5 | E10: =D10+F10 -> 5
C11: Durability | D11: 100 | E11: =D11+F11 -> 100
B14: PLEASE CHANGE ONLY YELLOW FIELDS

Sheet DEFAULT CLUBS-COMMON
H2: . | K2: Randomizer | L2: =RANDBETWEEN(1,3) -> 1 | M2: Mechanical Misake | N2: 1 | X2: CHARCTER | AA2: UPGRADES
L3: SemiRough | M3: SemiRough | U3: ROLL AFTER COEFFICIENT
F4: UPGRADES | L4: =VLOOKUP(L3,RECOVERY!$AA$8:$AP$10,2,FALSE) -> 1.4 | M4: =VLOOKUP(M3,RECOVERY!$AA$27:$AP$29,2,FALSE) -> 0.65 | N4: -1.5 | O4: 0 | P4: 1.5 | R4: 1/-1 | T4: 0.1 | U4: 1.33 | V4: -1.23
B5: COMMON | D5: Base Parameter | E5: Parameter | F5: =SUM(F6:F11)&"/25" -> 0/25 | G5: Base Rar Dist | H5: SHOT DISTANCE | I5: ACC. Coeff | J5: Shot Power Multiplyer | K5: ACC. DEVIATION | L5: REC. FOR ACC | M5: REC. FOR POWER | N5: TOP SPIN | O5: NO SPIN | P5: BACK SPIN | Q5: Deviation | R5: SIDE SPIN POWER | S5: Calculated Spin | T5: DEFAULT | U5: TOP SPIN | V5: BACK SPIN | X5: COMMON | Y5: Base Parameter | Z5: Parameter | AA5: =SUM(AA6:AA9)&"/25" -> 0/25 | AB5: Base Rar Dist
B6: Driver | C6: Power | D6: 135 | E6: =D6+F6 -> 135 | G6: 30 | H6: =$G$6+(E6/2)+$AB$6+(Z6/2)+$L$2 -> 143.5 | I6: =1-(E7/1000) -> 0.87 | J6: =ROUND(POWER(E6/100,0.5),3) -> 1.162 | K6: =(G8*J6*I6*N2) -> 20.2188 | L6: =1+(L4-1)*(1-E10/500) -> 1.396 | M6: =M4+((1-M4)*0.5*E10/400) -> 0.6521875 | N6: =(E9+(Q6*N4))/1.3 -> 26.230769 | O6: =(D9+(P6*O4))/1.3 -> 26.923077 | P6: =(E9+(Q6*P4))/1.3 -> 27.615385 | Q6: =3*(E8/100) -> 0.6 | R6: =E8*1*(VLOOKUP(B6,SPIN!$M$27:$N$40,2,FALSE)) -> 800 | S6: =E8*2*3.14/60 -> 2.0933333 | T6: =$S6*T4*8 -> 1.6746667 | U6: =$S6*U4*8 -> 22.273067 | V6: =$S6*V4*8 -> -20.5984 | X6: STRENGTH | Y6: 30 | Z6: =Y6+AA6 -> 30 | AB6: 30
C7: Accuracy | D7: 130 | E7: =D7+F7 -> 130 | G7: Mistake based on Rarity | H7: . | X7: CLUB CONTROL | Y7: 50 | Z7: =Y7+AA7 -> 50
C8: Spin | D8: 20 | E8: =D8+F8 -> 20 | G8: 20 | X8: STAMINA | Y8: 150 | Z8: =Y8+AA8 -> 150
C9: Loft | D9: 35 | E9: =D9+F9 -> 35 | X9: STAMINA REG | Y9: 5 | Z9: =Y9+AA9 -> 5
C10: Recovery | D10: 5 | E10: =D10+F10 -> 5
C11: Durability | D11: 100 | E11: =D11+F11 -> 100
H12: . | K12: Randomizer | L12: =RANDBETWEEN(0,3) -> 0 | M12: Mechanical Misake | N12: 1
L13: SemiRough | M13: SemiRough | U13: ROLL AFTER COEFFICIENT
F14: UPGRADES | L14: =VLOOKUP(L13,RECOVERY!$AA$8:$AP$10,3,FALSE) -> 1.4 | M14: =VLOOKUP(M13,RECOVERY!$AA$27:$AP$29,3,FALSE) -> 0.65 | N14: -1.5 | O14: 0 | P14: 1.5 | R14: 1/-1 | T14: 0.1 | U14: 1.33 | V14: -1.23
B15: COMMON | D15: Base Parameter | E15: Parameter | F15: =SUM(F16:F21)&"/25" -> 0/25 | G15: Base Rar Dist | H15: SHOT DISTANCE | I15: ACC. Coeff | J15: Shot Power Multiplyer | K15: ACC. DEVIATION | L15: REC. FOR ACC | M15: REC. FOR POWER | N15: TOP SPIN | O15: NO SPIN | P15: BACK SPIN | Q15: Deviation | R15: SIDE SPIN POWER | S15: Calculated Spin | T15: DEFAULT | U15: TOP SPIN | V15: BACK SPIN
B16: 3-Wood | C16: Power | D16: 100 | E16: =D16+F16 -> 100 | G16: 30 | H16: =$G$6+(E16/2)+$AB$6+(Z16/2)+$L$2 -> 111 | I16: =1-(E17/1000) -> 0.855 | J16: =ROUND(POWER(E16/100,0.5),3) -> 1 | K16: =(G18*J16*I16*N12) -> 17.1 | L16: =1+(L14-1)*(1-E20/500) -> 1.396 | M16: =M14+((1-M14)*0.5*E20/400) -> 0.6521875 | N16: =(E19+(Q16*N14))/1.3 -> 25.884615 | O16: =(D19+(P16*O14))/1.3 -> 26.923077 | P16: =(E19+(Q16*P14))/1.3 -> 27.961538 | Q16: =3*(E18/100) -> 0.9 | R16: =E18*1*(VLOOKUP(B16,SPIN!$M$27:$N$40,2,FALSE)) -> 1500 | S16: =E18*2*3.14/60 -> 3.14 | T16: =$S16*T14*8 -> 2.512 | U16: =$S16*U14*8 -> 33.4096 | V16: =$S16*V14*8 -> -30.8976
C17: Accuracy | D17: 145 | E17: =D17+F17 -> 145 | G17: Mistake based on Rarity
C18: Spin | D18: 30 | E18: =D18+F18 -> 30 | G18: 20
C19: Loft | D19: 35 | E19: =D19+F19 -> 35
C20: Recovery | D20: 5 | E20: =D20+F20 -> 5
C21: Durability | D21: 100 | E21: =D21+F21 -> 100
H22: . | K22: Randomizer | L22: =RANDBETWEEN(0,3) -> 2 | M22: Mechanical Misake | N22: 1
L23: SemiRough | M23: SemiRough | U23: ROLL AFTER COEFFICIENT
F24: UPGRADES | L24: =VLOOKUP(L23,RECOVERY!$AA$8:$AP$10,4,FALSE) -> 1.4 | M24: =VLOOKUP(M23,RECOVERY!$AA$27:$AP$29,4,FALSE) -> 0.65 | N24: -1.5 | O24: 0 | P24: 1.5 | R24: 1/-1 | T24: 0.1 | U24: 1.33 | V24: -1.23
B25: COMMON | D25: Base Parameter | E25: Parameter | F25: =SUM(F26:F31)&"/25" -> 0/25 | G25: Base Rar Dist | H25: SHOT DISTANCE | I25: ACC. Coeff | J25: Shot Power Multiplyer | K25: ACC. DEVIATION | L25: REC. FOR ACC | M25: REC. FOR POWER | N25: TOP SPIN | O25: NO SPIN | P25: BACK SPIN | Q25: Deviation | R25: SIDE SPIN POWER | S25: Calculated Spin | T25: DEFAULT | U25: TOP SPIN | V25: BACK SPIN
B26: 5-Wood | C26: Power | D26: 75 | E26: =D26+F26 -> 75 | G26: 30 | H26: =$G$6+(E26/2)+$AB$6+(Z26/2)+$L$2 -> 98.5 | I26: =1-(E27/1000) -> 0.855 | J26: =ROUND(POWER(E26/100,0.5),3) -> 0.866 | K26: =(G28*J26*I26*N22) -> 14.8086 | L26: =1+(L24-1)*(1-E30/500) -> 1.396 | M26: =M24+((1-M24)*0.5*E30/400) -> 0.6521875 | N26: =(E29+(Q26*N24))/1.3 -> 25.884615 | O26: =(D29+(P26*O24))/1.3 -> 26.923077 | P26: =(E29+(Q26*P24))/1.3 -> 27.961538 | Q26: =3*(E28/100) -> 0.9 | R26: =E28*1*(VLOOKUP(B26,SPIN!$M$27:$N$40,2,FALSE)) -> 1500 | S26: =E28*2*3.14/60 -> 3.14 | T26: =$S26*T24*8 -> 2.512 | U26: =$S26*U24*8 -> 33.4096 | V26: =$S26*V24*8 -> -30.8976
C27: Accuracy | D27: 145 | E27: =D27+F27 -> 145 | G27: Mistake based on Rarity
C28: Spin | D28: 30 | E28: =D28+F28 -> 30 | G28: 20
C29: Loft | D29: 35 | E29: =D29+F29 -> 35
C30: Recovery | D30: 5 | E30: =D30+F30 -> 5
C31: Durability | D31: 100 | E31: =D31+F31 -> 100
H32: . | K32: Randomizer | L32: =RANDBETWEEN(0,3) -> 0 | M32: Mechanical Misake | N32: 1
L33: SemiRough | M33: SemiRough | U33: ROLL AFTER COEFFICIENT
F34: UPGRADES | L34: =VLOOKUP(L33,RECOVERY!$AA$8:$AP$10,5,FALSE) -> 1.4 | M34: =VLOOKUP(M33,RECOVERY!$AA$27:$AP$29,5,FALSE) -> 0.65 | N34: -1.5 | O34: 0 | P34: 1.5 | R34: 1/-1 | T34: 0.1 | U34: 1.33 | V34: -1.23
B35: COMMON | D35: Base Parameter | E35: Parameter | F35: =SUM(F36:F41)&"/25" -> 0/25 | G35: Base Rar Dist | H35: SHOT DISTANCE | I35: ACC. Coeff | J35: Shot Power Multiplyer | K35: ACC. DEVIATION | L35: REC. FOR ACC | M35: REC. FOR POWER | N35: TOP SPIN | O35: NO SPIN | P35: BACK SPIN | Q35: Deviation | R35: SIDE SPIN POWER | S35: Calculated Spin | T35: DEFAULT | U35: TOP SPIN | V35: BACK SPIN
B36: 7-Wood | C36: Power | D36: 75 | E36: =D36+F36 -> 75 | G36: 30 | H36: =$G$6+(E36/2)+$AB$6+(Z36/2)+$L$2 -> 98.5 | I36: =1-(E37/1000) -> 0.87 | J36: =ROUND(POWER(E36/100,0.5),3) -> 0.866 | K36: =(G38*J36*I36*N32) -> 15.0684 | L36: =1+(L34-1)*(1-E40/500) -> 1.396 | M36: =M34+((1-M34)*0.5*E40/400) -> 0.6521875 | N36: =(E39+(Q36*N34))/1.3 -> 24.846154 | O36: =(D39+(P36*O34))/1.3 -> 26.923077 | P36: =(E39+(Q36*P34))/1.3 -> 29 | Q36: =3*(E38/100) -> 1.8 | R36: =E38*1*(VLOOKUP(B36,SPIN!$M$27:$N$40,2,FALSE)) -> 3000 | S36: =E38*2*3.14/60 -> 6.28 | T36: =$S36*T34*8 -> 5.024 | U36: =$S36*U34*8 -> 66.8192 | V36: =$S36*V34*8 -> -61.7952
C37: Accuracy | D37: 130 | E37: =D37+F37 -> 130 | G37: Mistake based on Rarity
C38: Spin | D38: 60 | E38: =D38+F38 -> 60 | G38: 20
C39: Loft | D39: 35 | E39: =D39+F39 -> 35
C40: Recovery | D40: 5 | E40: =D40+F40 -> 5
C41: Durability | D41: 100 | E41: =D41+F41 -> 100
...

Sheet DEFAULT CLUBS-UNCOMMON
H2: . | K2: Randomizer | L2: =RANDBETWEEN(0,3) -> 3 | M2: Mechanical Misake | N2: 1 | X2: CHARCTER | AA2: UPGRADES
L3: SemiRough | M3: SemiRough | U3: ROLL AFTER COEFFICIENT
F4: UPGRADES | L4: =VLOOKUP(L3,RECOVERY!$AA$8:$AP$10,2,FALSE) -> 1.4 | M4: =VLOOKUP(M3,RECOVERY!$AA$27:$AP$29,2,FALSE) -> 0.65 | N4: -1.5 | O4: 0 | P4: 1.5 | R4: 1/-1 | T4: 0.1 | U4: 1.33 | V4: -1.23
B5: UNCOMMON | D5: Base Parameter | E5: Parameter | F5: =SUM(F6:F11)&"/55" -> 0/55 | G5: Base Rar Dist | H5: SHOT DISTANCE | I5: ACC. Coeff | J5: Shot Power Multiplyer | K5: ACC. DEVIATION | L5: REC. FOR ACC | M5: REC. FOR POWER | N5: TOP SPIN | O5: NO SPIN | P5: BACK SPIN | Q5: Deviation | R5: SIDE SPIN POWER | S5: Calculated Spin | T5: DEFAULT | U5: TOP SPIN | V5: BACK SPIN | X5: UNCOMMON | Y5: Base Parameter | Z5: Parameter | AA5: =SUM(AA6:AA9)&"/55" -> 0/55 | AB5: Base Rar Dist
B6: Driver | C6: Power | D6: 150 | E6: =D6+F6 -> 150 | G6: 35 | H6: =$G$6+(E6/2)+$AB$6+(Z6/2)+$L$2 -> 158 | I6: =1-(E7/1000) -> 0.8 | J6: =ROUND(POWER(E6/100,0.5),3) -> 1.225 | K6: =(G8*J6*I6*N2) -> 16.66 | L6: =1+(L4-1)*(1-E10/500) -> 1.3944 | M6: =M4+((1-M4)*0.5*E10/400) -> 0.6530625 | N6: =(E9+(Q6*N4))/1.3 -> 25.365385 | O6: =(D9+(P6*O4))/1.3 -> 26.923077 | P6: =(E9+(Q6*P4))/1.3 -> 28.480769 | Q6: =3*(E8/100) -> 1.35 | R6: =E8*1*(VLOOKUP(B6,SPIN!$M$27:$N$40,2,FALSE)) -> 1800 | S6: =E8*2*3.14/60 -> 4.71 | T6: =$S6*T4*8 -> 3.768 | U6: =$S6*U4*8 -> 50.1144 | V6: =$S6*V4*8 -> -46.3464 | X6: STRENGTH | Y6: 30 | Z6: =Y6+AA6 -> 30 | AB6: 30
C7: Accuracy | D7: 200 | E7: =D7+F7 -> 200 | G7: Mistake based on Rarity | H7: . | X7: CLUB CONTROL | Y7: 50 | Z7: =Y7+AA7 -> 50
C8: Spin | D8: 45 | E8: =D8+F8 -> 45 | G8: 17 | X8: STAMINA | Y8: 150 | Z8: =Y8+AA8 -> 150
C9: Loft | D9: ='DEFAULT CLUBS-COMMON'!D9 -> 35 | E9: =D9+F9 -> 35 | X9: STAMINA REG | Y9: 5 | Z9: =Y9+AA9 -> 5
C10: Recovery | D10: =D20-6 -> 7 | E10: =D10+F10 -> 7
C11: Durability | D11: 150 | E11: =D11+F11 -> 150
H12: . | K12: Randomizer | L12: =RANDBETWEEN(0,3) -> 0 | M12: Mechanical Misake | N12: 1
L13: SemiRough | M13: SemiRough | U13: ROLL AFTER COEFFICIENT
F14: UPGRADES | L14: =VLOOKUP(L13,RECOVERY!$AA$8:$AP$10,3,FALSE) -> 1.4 | M14: =VLOOKUP(M13,RECOVERY!$AA$27:$AP$29,3,FALSE) -> 0.65 | N14: -1.5 | O14: 0 | P14: 1.5 | R14: 1/-1 | T14: 0.1 | U14: 1.33 | V14: -1.23
B15: UNCOMMON | D15: Base Parameter | E15: Parameter | F15: =SUM(F16:F21)&"/55" -> 0/55 | G15: Base Rar Dist | H15: SHOT DISTANCE | I15: ACC. Coeff | J15: Shot Power Multiplyer | K15: ACC. DEVIATION | L15: REC. FOR ACC | M15: REC. FOR POWER | N15: TOP SPIN | O15: NO SPIN | P15: BACK SPIN | Q15: Deviation | R15: SIDE SPIN POWER | S15: Calculated Spin | T15: DEFAULT | U15: TOP SPIN | V15: BACK SPIN
B16: 3-Wood | C16: Power | D16: =D6-10 -> 140 | E16: =D16+F16 -> 140 | G16: 35 | H16: =$G$6+(E16/2)+$AB$6+(Z16/2)+$L$2 -> 138 | I16: =1-(E17/1000) -> 0.8 | J16: =ROUND(POWER(E16/100,0.5),3) -> 1.183 | K16: =(G18*J16*I16*N12) -> 16.0888 | L16: =1+(L14-1)*(1-E20/500) -> 1.3896 | M16: =M14+((1-M14)*0.5*E20/400) -> 0.6556875 | N16: =(E19+(Q16*N14))/1.3 -> 24.846154 | O16: =(D19+(P16*O14))/1.3 -> 26.923077 | P16: =(E19+(Q16*P14))/1.3 -> 29 | Q16: =3*(E18/100) -> 1.8 | R16: =E18*1*(VLOOKUP(B16,SPIN!$M$27:$N$40,2,FALSE)) -> 3000 | S16: =E18*2*3.14/60 -> 6.28 | T16: =$S16*T14*8 -> 5.024 | U16: =$S16*U14*8 -> 66.8192 | V16: =$S16*V14*8 -> -61.7952
C17: Accuracy | D17: 200 | E17: =D17+F17 -> 200 | G17: Mistake based on Rarity
C18: Spin | D18: 60 | E18: =D18+F18 -> 60 | G18: 17
C19: Loft | D19: ='DEFAULT CLUBS-COMMON'!D19 -> 35 | E19: =D19+F19 -> 35
C20: Recovery | D20: =D30 -> 13 | E20: =D20+F20 -> 13
C21: Durability | D21: =D11 -> 150 | E21: =D21+F21 -> 150
H22: . | K22: Randomizer | L22: =RANDBETWEEN(0,3) -> 3 | M22: Mechanical Misake | N22: 1
L23: SemiRough | M23: SemiRough | U23: ROLL AFTER COEFFICIENT
F24: UPGRADES | L24: =VLOOKUP(L23,RECOVERY!$AA$8:$AP$10,4,FALSE) -> 1.4 | M24: =VLOOKUP(M23,RECOVERY!$AA$27:$AP$29,4,FALSE) -> 0.65 | N24: -1.5 | O24: 0 | P24: 1.5 | R24: 1/-1 | T24: 0.1 | U24: 1.33 | V24: -1.23
B25: UNCOMMON | D25: Base Parameter | E25: Parameter | F25: =SUM(F26:F31)&"/55" -> 0/55 | G25: Base Rar Dist | H25: SHOT DISTANCE | I25: ACC. Coeff | J25: Shot Power Multiplyer | K25: ACC. DEVIATION | L25: REC. FOR ACC | M25: REC. FOR POWER | N25: TOP SPIN | O25: NO SPIN | P25: BACK SPIN | Q25: Deviation | R25: SIDE SPIN POWER | S25: Calculated Spin | T25: DEFAULT | U25: TOP SPIN | V25: BACK SPIN
B26: 5-Wood | C26: Power | D26: =D16-10 -> 130 | E26: =D26+F26 -> 130 | G26: 35 | H26: =$G$6+(E26/2)+$AB$6+(Z26/2)+$L$2 -> 133 | I26: =1-(E27/1000) -> 0.795 | J26: =ROUND(POWER(E26/100,0.5),3) -> 1.14 | K26: =(G28*J26*I26*N22) -> 15.4071 | L26: =1+(L24-1)*(1-E30/500) -> 1.3896 | M26: =M24+((1-M24)*0.5*E30/400) -> 0.6556875 | N26: =(E29+(Q26*N24))/1.3 -> 24.673077 | O26: =(D29+(P26*O24))/1.3 -> 26.923077 | P26: =(E29+(Q26*P24))/1.3 -> 29.173077 | Q26: =3*(E28/100) -> 1.95 | R26: =E28*1*(VLOOKUP(B26,SPIN!$M$27:$N$40,2,FALSE)) -> 3250 | S26: =E28*2*3.14/60 -> 6.8033333 | T26: =$S26*T24*8 -> 5.4426667 | U26: =$S26*U24*8 -> 72.387467 | V26: =$S26*V24*8 -> -66.9448
C27: Accuracy | D27: =D17+5 -> 205 | E27: =D27+F27 -> 205 | G27: Mistake based on Rarity
C28: Spin | D28: 65 | E28: =D28+F28 -> 65 | G28: 17
C29: Loft | D29: ='DEFAULT CLUBS-COMMON'!D29 -> 35 | E29: =D29+F29 -> 35
C30: Recovery | D30: =D40 -> 13 | E30: =D30+F30 -> 13
C31: Durability | D31: =D21 -> 150 | E31: =D31+F31 -> 150
H32: . | K32: Randomizer | L32: =RANDBETWEEN(0,3) -> 1 | M32: Mechanical Misake | N32: 1
L33: SemiRough | M33: SemiRough | U33: ROLL AFTER COEFFICIENT
F34: UPGRADES | L34: =VLOOKUP(L33,RECOVERY!$AA$8:$AP$10,5,FALSE) -> 1.4 | M34: =VLOOKUP(M33,RECOVERY!$AA$27:$AP$29,5,FALSE) -> 0.65 | N34: -1.5 | O34: 0 | P34: 1.5 | R34: 1/-1 | T34: 0.1 | U34: 1.33 | V34: -1.23
B35: UNCOMMON | D35: Base Parameter | E35: Parameter | F35: =SUM(F36:F41)&"/55" -> 0/55 | G35: Base Rar Dist | H35: SHOT DISTANCE | I35: ACC. Coeff | J35: Shot Power Multiplyer | K35: ACC. DEVIATION | L35: REC. FOR ACC | M35: REC. FOR POWER | N35: TOP SPIN | O35: NO SPIN | P35: BACK SPIN | Q35: Deviation | R35: SIDE SPIN POWER | S35: Calculated Spin | T35: DEFAULT | U35: TOP SPIN | V35: BACK SPIN
B36: 7-Wood | C36: Power | D36: =D26-10 -> 120 | E36: =D36+F36 -> 120 | G36: 35 | H36: =$G$6+(E36/2)+$AB$6+(Z36/2)+$L$2 -> 128 | I36: =1-(E37/1000) -> 0.795 | J36: =ROUND(POWER(E36/100,0.5),3) -> 1.095 | K36: =(G38*J36*I36*N32) -> 14.798925 | L36: =1+(L34-1)*(1-E40/500) -> 1.3896 | M36: =M34+((1-M34)*0.5*E40/400) -> 0.6556875 | N36: =(E39+(Q36*N34))/1.3 -> 24.534615 | O36: =(D39+(P36*O34))/1.3 -> 26.923077 | P36: =(E39+(Q36*P34))/1.3 -> 29.311538 | Q36: =3*(E38/100) -> 2.07 | R36: =E38*1*(VLOOKUP(B36,SPIN!$M$27:$N$40,2,FALSE)) -> 3450 | S36: =E38*2*3.14/60 -> 7.222 | T36: =$S36*T34*8 -> 5.7776 | U36: =$S36*U34*8 -> 76.84208 | V36: =$S36*V34*8 -> -71.06448
C37: Accuracy | D37: =D27 -> 205 | E37: =D37+F37 -> 205 | G37: Mistake based on Rarity
C38: Spin | D38: 69 | E38: =D38+F38 -> 69 | G38: 17
C39: Loft | D39: ='DEFAULT CLUBS-COMMON'!D39 -> 35 | E39: =D39+F39 -> 35
C40: Recovery | D40: =D50 -> 13 | E40: =D40+F40 -> 13
C41: Durability | D41: =D31 -> 150 | E41: =D41+F41 -> 150
...

Sheet DEFAULT CLUBS-RARE
H2: . | K2: Randomizer | L2: =RANDBETWEEN(0,3) -> 0 | M2: Mechanical Misake | N2: 1 | X2: CHARCTER | AA2: UPGRADES
L3: SemiRough | M3: SemiRough | U3: ROLL AFTER COEFFICIENT
F4: UPGRADES | L4: =VLOOKUP(L3,RECOVERY!$AA$8:$AP$10,2,FALSE) -> 1.4 | M4: =VLOOKUP(M3,RECOVERY!$AA$27:$AP$29,2,FALSE) -> 0.65 | N4: -1.5 | O4: 0 | P4: 1.5 | R4: 1/-1 | T4: 0.1 | U4: 1.33 | V4: -1.23
B5: RARE | D5: Base Parameter | E5: Parameter | F5: =SUM(F6:F11)&"/100" -> 100/100 | G5: Base Rar Dist | H5: SHOT DISTANCE | I5: ACC. Coeff | J5: Shot Power Multiplyer | K5: ACC. DEVIATION | L5: REC. FOR ACC | M5: REC. FOR POWER | N5: TOP SPIN | O5: NO SPIN | P5: BACK SPIN | Q5: Deviation | R5: SIDE SPIN POWER | S5: Calculated Spin | T5: DEFAULT | U5: TOP SPIN | V5: BACK SPIN | X5: RARE | Y5: Base Parameter | Z5: Parameter | AA5: =SUM(AA6:AA9)&"/55" -> 0/55 | AB5: Base Rar Dist
B6: Driver | C6: Power | D6: 180 | E6: =D6+F6 -> 180 | G6: 40 | H6: =$G$6+(E6/2)+$AB$6+(Z6/2)+$L$2 -> 175 | I6: =1-(E7/1000) -> 0.75 | J6: =ROUND(POWER(E6/100,0.5),3) -> 1.342 | K6: =(G8*J6*I6*N2) -> 14.091 | L6: =1+(L4-1)*(1-E10/500) -> 1.3024 | M6: =M4+((1-M4)*0.5*E10/400) -> 0.703375 | N6: =(E9+(Q6*N4))/1.3 -> 24.673077 | O6: =(D9+(P6*O4))/1.3 -> 26.923077 | P6: =(E9+(Q6*P4))/1.3 -> 29.173077 | Q6: =3*(E8/100) -> 1.95 | R6: =E8*1*(VLOOKUP(B6,SPIN!$M$27:$N$40,2,FALSE)) -> 2600 | S6: =E8*2*3.14/60 -> 6.8033333 | T6: =$S6*T4*8 -> 5.4426667 | U6: =$S6*U4*8 -> 72.387467 | V6: =$S6*V4*8 -> -66.9448 | X6: STRENGTH | Y6: 30 | Z6: =Y6+AA6 -> 30 | AB6: 30
C7: Accuracy | D7: 250 | E7: =D7+F7 -> 250 | G7: Mistake based on Rarity | H7: . | X7: CLUB CONTROL | Y7: 50 | Z7: =Y7+AA7 -> 50
C8: Spin | D8: 65 | E8: =D8+F8 -> 65 | G8: 14 | X8: STAMINA | Y8: 150 | Z8: =Y8+AA8 -> 150
C9: Loft | D9: ='DEFAULT CLUBS-COMMON'!D9 -> 35 | E9: =D9+F9 -> 35 | X9: STAMINA REG | Y9: 5 | Z9: =Y9+AA9 -> 5
C10: Recovery | D10: =D20-6 -> 22 | E10: =D10+F10 -> 122 | F10: 100
C11: Durability | D11: 200 | E11: =D11+F11 -> 200
H12: . | K12: Randomizer | L12: =RANDBETWEEN(0,3) -> 2 | M12: Mechanical Misake | N12: 1
L13: SemiRough | M13: SemiRough | U13: ROLL AFTER COEFFICIENT
F14: UPGRADES | L14: =VLOOKUP(L13,RECOVERY!$AA$8:$AP$10,3,FALSE) -> 1.4 | M14: =VLOOKUP(M13,RECOVERY!$AA$27:$AP$29,3,FALSE) -> 0.65 | N14: -1.5 | O14: 0 | P14: 1.5 | R14: 1/-1 | T14: 0.1 | U14: 1.33 | V14: -1.23
B15: RARE | D15: Base Parameter | E15: Parameter | F15: =F5 -> 100/100 | G15: Base Rar Dist | H15: SHOT DISTANCE | I15: ACC. Coeff | J15: Shot Power Multiplyer | K15: ACC. DEVIATION | L15: REC. FOR ACC | M15: REC. FOR POWER | N15: TOP SPIN | O15: NO SPIN | P15: BACK SPIN | Q15: Deviation | R15: SIDE SPIN POWER | S15: Calculated Spin | T15: DEFAULT | U15: TOP SPIN | V15: BACK SPIN
B16: 3-Wood | C16: Power | D16: =D6-10 -> 170 | E16: =D16+F16 -> 170 | G16: =G6 -> 40 | H16: =$G$6+(E16/2)+$AB$6+(Z16/2)+$L$2 -> 155 | I16: =1-(E17/1000) -> 0.75 | J16: =ROUND(POWER(E16/100,0.5),3) -> 1.304 | K16: =(G18*J16*I16*N12) -> 13.692 | L16: =1+(L14-1)*(1-E20/500) -> 1.3776 | M16: =M14+((1-M14)*0.5*E20/400) -> 0.66225 | N16: =(E19+(Q16*N14))/1.3 -> 24.153846 | O16: =(D19+(P16*O14))/1.3 -> 26.923077 | P16: =(E19+(Q16*P14))/1.3 -> 29.692308 | Q16: =3*(E18/100) -> 2.4 | R16: =E18*1*(VLOOKUP(B16,SPIN!$M$27:$N$40,2,FALSE)) -> 4000 | S16: =E18*2*3.14/60 -> 8.3733333 | T16: =$S16*T14*8 -> 6.6986667 | U16: =$S16*U14*8 -> 89.092267 | V16: =$S16*V14*8 -> -82.3936
C17: Accuracy | D17: =D7 -> 250 | E17: =D17+F17 -> 250 | G17: Mistake based on Rarity
C18: Spin | D18: 80 | E18: =D18+F18 -> 80 | G18: =G8 -> 14
C19: Loft | D19: ='DEFAULT CLUBS-COMMON'!D19 -> 35 | E19: =D19+F19 -> 35
C20: Recovery | D20: =D30 -> 28 | E20: =D20+F20 -> 28
C21: Durability | D21: =D11 -> 200 | E21: =D21+F21 -> 200
H22: . | K22: Randomizer | L22: =RANDBETWEEN(0,3) -> 0 | M22: Mechanical Misake | N22: 1
L23: SemiRough | M23: SemiRough | U23: ROLL AFTER COEFFICIENT
F24: UPGRADES | L24: =VLOOKUP(L23,RECOVERY!$AA$8:$AP$10,4,FALSE) -> 1.4 | M24: =VLOOKUP(M23,RECOVERY!$AA$27:$AP$29,4,FALSE) -> 0.65 | N24: -1.5 | O24: 0 | P24: 1.5 | R24: 1/-1 | T24: 0.1 | U24: 1.33 | V24: -1.23
B25: RARE | D25: Base Parameter | E25: Parameter | F25: =F15 -> 100/100 | G25: Base Rar Dist | H25: SHOT DISTANCE | I25: ACC. Coeff | J25: Shot Power Multiplyer | K25: ACC. DEVIATION | L25: REC. FOR ACC | M25: REC. FOR POWER | N25: TOP SPIN | O25: NO SPIN | P25: BACK SPIN | Q25: Deviation | R25: SIDE SPIN POWER | S25: Calculated Spin | T25: DEFAULT | U25: TOP SPIN | V25: BACK SPIN
B26: 5-Wood | C26: Power | D26: =D16-10 -> 160 | E26: =D26+F26 -> 160 | G26: =G16 -> 40 | H26: =$G$6+(E26/2)+$AB$6+(Z26/2)+$L$2 -> 150 | I26: =1-(E27/1000) -> 0.745 | J26: =ROUND(POWER(E26/100,0.5),3) -> 1.265 | K26: =(G28*J26*I26*N22) -> 13.19395 | L26: =1+(L24-1)*(1-E30/500) -> 1.3776 | M26: =M24+((1-M24)*0.5*E30/400) -> 0.66225 | N26: =(E29+(Q26*N24))/1.3 -> 24.153846 | O26: =(D29+(P26*O24))/1.3 -> 26.923077 | P26: =(E29+(Q26*P24))/1.3 -> 29.692308 | Q26: =3*(E28/100) -> 2.4 | R26: =E28*1*(VLOOKUP(B26,SPIN!$M$27:$N$40,2,FALSE)) -> 4000 | S26: =E28*2*3.14/60 -> 8.3733333 | T26: =$S26*T24*8 -> 6.6986667 | U26: =$S26*U24*8 -> 89.092267 | V26: =$S26*V24*8 -> -82.3936
C27: Accuracy | D27: =D17+5 -> 255 | E27: =D27+F27 -> 255 | G27: Mistake based on Rarity
C28: Spin | D28: 80 | E28: =D28+F28 -> 80 | G28: =G18 -> 14
C29: Loft | D29: ='DEFAULT CLUBS-COMMON'!D29 -> 35 | E29: =D29+F29 -> 35
C30: Recovery | D30: =D40 -> 28 | E30: =D30+F30 -> 28
C31: Durability | D31: =D21 -> 200 | E31: =D31+F31 -> 200
H32: . | K32: Randomizer | L32: =RANDBETWEEN(0,3) -> 0 | M32: Mechanical Misake | N32: 1
L33: SemiRough | M33: SemiRough | U33: ROLL AFTER COEFFICIENT
F34: UPGRADES | L34: =VLOOKUP(L33,RECOVERY!$AA$8:$AP$10,5,FALSE) -> 1.4 | M34: =VLOOKUP(M33,RECOVERY!$AA$27:$AP$29,5,FALSE) -> 0.65 | N34: -1.5 | O34: 0 | P34: 1.5 | R34: 1/-1 | T34: 0.1 | U34: 1.33 | V34: -1.23
B35: RARE | D35: Base Parameter | E35: Parameter | F35: =F25 -> 100/100 | G35: Base Rar Dist | H35: SHOT DISTANCE | I35: ACC. Coeff | J35: Shot Power Multiplyer | K35: ACC. DEVIATION | L35: REC. FOR ACC | M35: REC. FOR POWER | N35: TOP SPIN | O35: NO SPIN | P35: BACK SPIN | Q35: Deviation | R35: SIDE SPIN POWER | S35: Calculated Spin | T35: DEFAULT | U35: TOP SPIN | V35: BACK SPIN
B36: 7-Wood | C36: Power | D36: =D26-10 -> 150 | E36: =D36+F36 -> 150 | G36: =G26 -> 40 | H36: =$G$6+(E36/2)+$AB$6+(Z36/2)+$L$2 -> 145 | I36: =1-(E37/1000) -> 0.745 | J36: =ROUND(POWER(E36/100,0.5),3) -> 1.225 | K36: =(G38*J36*I36*N32) -> 12.77675 | L36: =1+(L34-1)*(1-E40/500) -> 1.3776 | M36: =M34+((1-M34)*0.5*E40/400) -> 0.66225 | N36: =(E39+(Q36*N34))/1.3 -> 24.015385 | O36: =(D39+(P36*O34))/1.3 -> 26.923077 | P36: =(E39+(Q36*P34))/1.3 -> 29.830769 | Q36: =3*(E38/100) -> 2.52 | R36: =E38*1*(VLOOKUP(B36,SPIN!$M$27:$N$40,2,FALSE)) -> 4200 | S36: =E38*2*3.14/60 -> 8.792 | T36: =$S36*T34*8 -> 7.0336 | U36: =$S36*U34*8 -> 93.54688 | V36: =$S36*V34*8 -> -86.51328
C37: Accuracy | D37: =D27 -> 255 | E37: =D37+F37 -> 255 | G37: Mistake based on Rarity
C38: Spin | D38: 84 | E38: =D38+F38 -> 84 | G38: =G28 -> 14
C39: Loft | D39: ='DEFAULT CLUBS-COMMON'!D39 -> 35 | E39: =D39+F39 -> 35
C40: Recovery | D40: =D50 -> 28 | E40: =D40+F40 -> 28
C41: Durability | D41: =D31 -> 200 | E41: =D41+F41 -> 200
...

Sheet DEFAULT CLUBS-MYTHIC
H2: . | K2: Randomizer | L2: =RANDBETWEEN(0,3) -> 1 | M2: Mechanical Misake | N2: 1 | X2: CHARCTER | AA2: UPGRADES
L3: SemiRough | M3: SemiRough | U3: ROLL AFTER COEFFICIENT
F4: UPGRADES | L4: =VLOOKUP(L3,RECOVERY!$AA$8:$AP$10,2,FALSE) -> 1.4 | M4: =VLOOKUP(M3,RECOVERY!$AA$27:$AP$29,2,FALSE) -> 0.65 | N4: -1.5 | O4: 0 | P4: 1.5 | R4: 1/-1 | T4: 0.1 | U4: 1.33 | V4: -1.23
B5: MYTHIC | D5: Base Parameter | E5: Parameter | F5: =SUM(F6:F11)&"/160" -> 0/160 | G5: Base Rar Dist | H5: SHOT DISTANCE | I5: ACC. Coeff | J5: Shot Power Multiplyer | K5: ACC. DEVIATION | L5: REC. FOR ACC | M5: REC. FOR POWER | N5: TOP SPIN | O5: NO SPIN | P5: BACK SPIN | Q5: Deviation | R5: SIDE SPIN POWER | S5: Calculated Spin | T5: DEFAULT | U5: TOP SPIN | V5: BACK SPIN | X5: MYTHIC | Y5: Base Parameter | Z5: Parameter | AA5: =SUM(AA6:AA9)&"/55" -> 0/55 | AB5: Base Rar Dist
B6: Driver | C6: Power | D6: 210 | E6: =D6+F6 -> 210 | G6: 45 | H6: =$G$6+(E6/2)+$AB$6+(Z6/2)+$L$2 -> 196 | I6: =1-(E7/1000) -> 0.7 | J6: =ROUND(POWER(E6/100,0.5),3) -> 1.449 | K6: =(G8*J6*I6*N2) -> 11.1573 | L6: =1+(L4-1)*(1-E10/500) -> 1.3584 | M6: =M4+((1-M4)*0.5*E10/400) -> 0.67275 | N6: =(E9+(Q6*N4))/1.3 -> 24.5 | O6: =(D9+(P6*O4))/1.3 -> 26.923077 | P6: =(E9+(Q6*P4))/1.3 -> 29.346154 | Q6: =3*(E8/100) -> 2.1 | R6: =E8*1*(VLOOKUP(B6,SPIN!$M$27:$N$40,2,FALSE)) -> 2800 | S6: =E8*2*3.14/60 -> 7.3266667 | T6: =$S6*T4*8 -> 5.8613333 | U6: =$S6*U4*8 -> 77.955733 | V6: =$S6*V4*8 -> -72.0944 | X6: STRENGTH | Y6: 30 | Z6: =Y6+AA6 -> 30 | AB6: 30
C7: Accuracy | D7: 300 | E7: =D7+F7 -> 300 | G7: Mistake based on Rarity | H7: . | X7: CLUB CONTROL | Y7: 50 | Z7: =Y7+AA7 -> 50
C8: Spin | D8: =D18-15 -> 70 | E8: =D8+F8 -> 70 | G8: 11 | X8: STAMINA | Y8: 150 | Z8: =Y8+AA8 -> 150
C9: Loft | D9: ='DEFAULT CLUBS-COMMON'!D9 -> 35 | E9: =D9+F9 -> 35 | X9: STAMINA REG | Y9: 5 | Z9: =Y9+AA9 -> 5
C10: Recovery | D10: =D20-6 -> 52 | E10: =D10+F10 -> 52
C11: Durability | D11: 250 | E11: =D11+F11 -> 250
H12: . | K12: Randomizer | L12: =RANDBETWEEN(0,15) -> 14 | M12: Mechanical Misake | N12: 1
L13: SemiRough | M13: SemiRough | U13: ROLL AFTER COEFFICIENT
F14: UPGRADES | L14: =VLOOKUP(L13,RECOVERY!$AA$8:$AP$10,3,FALSE) -> 1.4 | M14: =VLOOKUP(M13,RECOVERY!$AA$27:$AP$29,3,FALSE) -> 0.65 | N14: -1.5 | O14: 0 | P14: 1.5 | R14: 1/-1 | T14: 0.1 | U14: 1.33 | V14: -1.23
B15: MYTHIC | D15: Base Parameter | E15: Parameter | F15: =F5 -> 0/160 | G15: Base Rar Dist | H15: SHOT DISTANCE | I15: ACC. Coeff | J15: Shot Power Multiplyer | K15: ACC. DEVIATION | L15: REC. FOR ACC | M15: REC. FOR POWER | N15: TOP SPIN | O15: NO SPIN | P15: BACK SPIN | Q15: Deviation | R15: SIDE SPIN POWER | S15: Calculated Spin | T15: DEFAULT | U15: TOP SPIN | V15: BACK SPIN
B16: 3-Wood | C16: Power | D16: =D6-10 -> 200 | E16: =D16+F16 -> 200 | G16: =G6 -> 45 | H16: =$G$6+(E16/2)+$AB$6+(Z16/2)+$L$2 -> 176 | I16: =1-(E17/1000) -> 0.7 | J16: =ROUND(POWER(E16/100,0.5),3) -> 1.414 | K16: =(G18*J16*I16*N12) -> 10.8878 | L16: =1+(L14-1)*(1-E20/500) -> 1.3536 | M16: =M14+((1-M14)*0.5*E20/400) -> 0.675375 | N16: =(E19+(Q16*N14))/1.3 -> 23.980769 | O16: =(D19+(P16*O14))/1.3 -> 26.923077 | P16: =(E19+(Q16*P14))/1.3 -> 29.865385 | Q16: =3*(E18/100) -> 2.55 | R16: =E18*1*(VLOOKUP(B16,SPIN!$M$27:$N$40,2,FALSE)) -> 4250 | S16: =E18*2*3.14/60 -> 8.8966667 | T16: =$S16*T14*8 -> 7.1173333 | U16: =$S16*U14*8 -> 94.660533 | V16: =$S16*V14*8 -> -87.5432
C17: Accuracy | D17: =D7 -> 300 | E17: =D17+F17 -> 300 | G17: Mistake based on Rarity
C18: Spin | D18: =D28 -> 85 | E18: =D18+F18 -> 85 | G18: =G8 -> 11
C19: Loft | D19: ='DEFAULT CLUBS-COMMON'!D19 -> 35 | E19: =D19+F19 -> 35
C20: Recovery | D20: =D30 -> 58 | E20: =D20+F20 -> 58
C21: Durability | D21: =D11 -> 250 | E21: =D21+F21 -> 250
H22: . | K22: Randomizer | L22: =RANDBETWEEN(0,3) -> 0 | M22: Mechanical Misake | N22: 1
L23: SemiRough | M23: SemiRough | U23: ROLL AFTER COEFFICIENT
F24: UPGRADES | L24: =VLOOKUP(L23,RECOVERY!$AA$8:$AP$10,4,FALSE) -> 1.4 | M24: =VLOOKUP(M23,RECOVERY!$AA$27:$AP$29,4,FALSE) -> 0.65 | N24: -1.5 | O24: 0 | P24: 1.5 | R24: 1/-1 | T24: 0.1 | U24: 1.33 | V24: -1.23
B25: MYTHIC | D25: Base Parameter | E25: Parameter | F25: =F15 -> 0/160 | G25: Base Rar Dist | H25: SHOT DISTANCE | I25: ACC. Coeff | J25: Shot Power Multiplyer | K25: ACC. DEVIATION | L25: REC. FOR ACC | M25: REC. FOR POWER | N25: TOP SPIN | O25: NO SPIN | P25: BACK SPIN | Q25: Deviation | R25: SIDE SPIN POWER | S25: Calculated Spin | T25: DEFAULT | U25: TOP SPIN | V25: BACK SPIN
B26: 5-Wood | C26: Power | D26: =D16-10 -> 190 | E26: =D26+F26 -> 190 | G26: =G16 -> 45 | H26: =$G$6+(E26/2)+$AB$6+(Z26/2)+$L$2 -> 171 | I26: =1-(E27/1000) -> 0.695 | J26: =ROUND(POWER(E26/100,0.5),3) -> 1.378 | K26: =(G28*J26*I26*N22) -> 10.53481 | L26: =1+(L24-1)*(1-E30/500) -> 1.3536 | M26: =M24+((1-M24)*0.5*E30/400) -> 0.675375 | N26: =(E29+(Q26*N24))/1.3 -> 23.980769 | O26: =(D29+(P26*O24))/1.3 -> 26.923077 | P26: =(E29+(Q26*P24))/1.3 -> 29.865385 | Q26: =3*(E28/100) -> 2.55 | R26: =E28*1*(VLOOKUP(B26,SPIN!$M$27:$N$40,2,FALSE)) -> 4250 | S26: =E28*2*3.14/60 -> 8.8966667 | T26: =$S26*T24*8 -> 7.1173333 | U26: =$S26*U24*8 -> 94.660533 | V26: =$S26*V24*8 -> -87.5432
C27: Accuracy | D27: =D17+5 -> 305 | E27: =D27+F27 -> 305 | G27: Mistake based on Rarity
C28: Spin | D28: =D48 -> 85 | E28: =D28+F28 -> 85 | G28: =G18 -> 11
C29: Loft | D29: ='DEFAULT CLUBS-COMMON'!D29 -> 35 | E29: =D29+F29 -> 35
C30: Recovery | D30: =D40 -> 58 | E30: =D30+F30 -> 58
C31: Durability | D31: =D21 -> 250 | E31: =D31+F31 -> 250
H32: . | K32: Randomizer | L32: =RANDBETWEEN(0,3) -> 1 | M32: Mechanical Misake | N32: 1
L33: SemiRough | M33: SemiRough | U33: ROLL AFTER COEFFICIENT
F34: UPGRADES | L34: =VLOOKUP(L33,RECOVERY!$AA$8:$AP$10,5,FALSE) -> 1.4 | M34: =VLOOKUP(M33,RECOVERY!$AA$27:$AP$29,5,FALSE) -> 0.65 | N34: -1.5 | O34: 0 | P34: 1.5 | R34: 1/-1 | T34: 0.1 | U34: 1.33 | V34: -1.23
B35: MYTHIC | D35: Base Parameter | E35: Parameter | F35: =F25 -> 0/160 | G35: Base Rar Dist | H35: SHOT DISTANCE | I35: ACC. Coeff | J35: Shot Power Multiplyer | K35: ACC. DEVIATION | L35: REC. FOR ACC | M35: REC. FOR POWER | N35: TOP SPIN | O35: NO SPIN | P35: BACK SPIN | Q35: Deviation | R35: SIDE SPIN POWER | S35: Calculated Spin | T35: DEFAULT | U35: TOP SPIN | V35: BACK SPIN
B36: 7-Wood | C36: Power | D36: =D26-10 -> 180 | E36: =D36+F36 -> 180 | G36: =G26 -> 45 | H36: =$G$6+(E36/2)+$AB$6+(Z36/2)+$L$2 -> 166 | I36: =1-(E37/1000) -> 0.695 | J36: =ROUND(POWER(E36/100,0.5),3) -> 1.342 | K36: =(G38*J36*I36*N32) -> 10.25959 | L36: =1+(L34-1)*(1-E40/500) -> 1.3536 | M36: =M34+((1-M34)*0.5*E40/400) -> 0.675375 | N36: =(E39+(Q36*N34))/1.3 -> 23.842308 | O36: =(D39+(P36*O34))/1.3 -> 26.923077 | P36: =(E39+(Q36*P34))/1.3 -> 30.003846 | Q36: =3*(E38/100) -> 2.67 | R36: =E38*1*(VLOOKUP(B36,SPIN!$M$27:$N$40,2,FALSE)) -> 4450 | S36: =E38*2*3.14/60 -> 9.3153333 | T36: =$S36*T34*8 -> 7.4522667 | U36: =$S36*U34*8 -> 99.115147 | V36: =$S36*V34*8 -> -91.66288
C37: Accuracy | D37: =D27 -> 305 | E37: =D37+F37 -> 305 | G37: Mistake based on Rarity
C38: Spin | D38: =D48+4 -> 89 | E38: =D38+F38 -> 89 | G38: =G28 -> 11
C39: Loft | D39: ='DEFAULT CLUBS-COMMON'!D39 -> 35 | E39: =D39+F39 -> 35
C40: Recovery | D40: =D50 -> 58 | E40: =D40+F40 -> 58
C41: Durability | D41: =D31 -> 250 | E41: =D41+F41 -> 250
...

Sheet DEFAULT CLUBS-LEGENDARY
H2: . | K2: Randomizer | L2: 15 | M2: Mechanical Misake | N2: 1 | X2: CHARCTER | AA2: UPGRADES
L3: SemiRough | M3: SemiRough | U3: ROLL AFTER COEFFICIENT
F4: UPGRADES | L4: =VLOOKUP(L3,RECOVERY!$AA$8:$AP$10,2,FALSE) -> 1.4 | M4: =VLOOKUP(M3,RECOVERY!$AA$27:$AP$29,2,FALSE) -> 0.65 | N4: -1.5 | O4: 0 | P4: 1.5 | R4: 1/-1 | T4: 0.1 | U4: 1.33 | V4: -1.23
B5: LEGENDARY | D5: Base Parameter | E5: Parameter | F5: =SUM(F6:F11)&"/235" -> 0/235 | G5: Base Rar Dist | H5: SHOT DISTANCE | I5: ACC. Coeff | J5: Shot Power Multiplyer | K5: ACC. DEVIATION | L5: REC. FOR ACC | M5: REC. FOR POWER | N5: TOP SPIN | O5: NO SPIN | P5: BACK SPIN | Q5: Deviation | R5: SIDE SPIN POWER | S5: Calculated Spin | T5: DEFAULT | U5: TOP SPIN | V5: BACK SPIN | X5: LEGENDARY | Y5: Base Parameter | Z5: Parameter | AA5: =SUM(AA6:AA9)&"/55" -> 0/55 | AB5: Base Rar Dist
B6: Driver | C6: Power | D6: 270 | E6: =D6+F6 -> 270 | G6: 50 | H6: =$G$6+(E6/2)+$AB$6+(Z6/2)+$L$2 -> 245 | I6: =1-(E7/1000) -> 0.65 | J6: =ROUND(POWER(E6/100,0.5),3) -> 1.643 | K6: =(G8*J6*I6*N2) -> 7.47565 | L6: =1+(L4-1)*(1-E10/500) -> 1.3184 | M6: =M4+((1-M4)*0.5*E10/400) -> 0.694625 | N6: =(E9+(Q6*N4))/1.3 -> 23.980769 | O6: =(D9+(P6*O4))/1.3 -> 26.923077 | P6: =(E9+(Q6*P4))/1.3 -> 29.865385 | Q6: =3*(E8/100) -> 2.55 | R6: =E8*1*(VLOOKUP(B6,SPIN!$M$27:$N$40,2,FALSE)) -> 3400 | S6: =E8*2*3.14/60 -> 8.8966667 | T6: =$S6*T4*8 -> 7.1173333 | U6: =$S6*U4*8 -> 94.660533 | V6: =$S6*V4*8 -> -87.5432 | X6: STRENGTH | Y6: 30 | Z6: =Y6+AA6 -> 30 | AB6: 30
C7: Accuracy | D7: 350 | E7: =D7+F7 -> 350 | G7: Mistake based on Rarity | H7: . | X7: CLUB CONTROL | Y7: 50 | Z7: =Y7+AA7 -> 50
C8: Spin | D8: =D18-15 -> 85 | E8: =D8+F8 -> 85 | G8: 7 | X8: STAMINA | Y8: 150 | Z8: =Y8+AA8 -> 150
C9: Loft | D9: ='DEFAULT CLUBS-COMMON'!D9 -> 35 | E9: =D9+F9 -> 35 | X9: STAMINA REG | Y9: 5 | Z9: =Y9+AA9 -> 5
C10: Recovery | D10: =D20-6 -> 102 | E10: =D10+F10 -> 102
C11: Durability | D11: 300 | E11: =D11+F11 -> 300
H12: . | K12: Randomizer | L12: =RANDBETWEEN(0,3) -> 3 | M12: Mechanical Misake | N12: 1
L13: SemiRough | M13: SemiRough | U13: ROLL AFTER COEFFICIENT
F14: UPGRADES | L14: =VLOOKUP(L13,RECOVERY!$AA$8:$AP$10,3,FALSE) -> 1.4 | M14: =VLOOKUP(M13,RECOVERY!$AA$27:$AP$29,3,FALSE) -> 0.65 | N14: -1.5 | O14: 0 | P14: 1.5 | R14: 1/-1 | T14: 0.1 | U14: 1.33 | V14: -1.23
B15: LEGENDARY | D15: Base Parameter | E15: Parameter | F15: =F5 -> 0/235 | G15: Base Rar Dist | H15: SHOT DISTANCE | I15: ACC. Coeff | J15: Shot Power Multiplyer | K15: ACC. DEVIATION | L15: REC. FOR ACC | M15: REC. FOR POWER | N15: TOP SPIN | O15: NO SPIN | P15: BACK SPIN | Q15: Deviation | R15: SIDE SPIN POWER | S15: Calculated Spin | T15: DEFAULT | U15: TOP SPIN | V15: BACK SPIN
B16: 3-Wood | C16: Power | D16: =D6-10 -> 260 | E16: =D16+F16 -> 260 | G16: =G6 -> 50 | H16: =$G$6+(E16/2)+$AB$6+(Z16/2)+$L$2 -> 225 | I16: =1-(E17/1000) -> 0.65 | J16: =ROUND(POWER(E16/100,0.5),3) -> 1.612 | K16: =(G18*J16*I16*N12) -> 7.3346 | L16: =1+(L14-1)*(1-E20/500) -> 1.3136 | M16: =M14+((1-M14)*0.5*E20/400) -> 0.69725 | N16: =(E19+(Q16*N14))/1.3 -> 23.461538 | O16: =(D19+(P16*O14))/1.3 -> 26.923077 | P16: =(E19+(Q16*P14))/1.3 -> 30.384615 | Q16: =3*(E18/100) -> 3 | R16: =E18*1*(VLOOKUP(B16,SPIN!$M$27:$N$40,2,FALSE)) -> 5000 | S16: =E18*2*3.14/60 -> 10.466667 | T16: =$S16*T14*8 -> 8.3733333 | U16: =$S16*U14*8 -> 111.36533 | V16: =$S16*V14*8 -> -102.992
C17: Accuracy | D17: =D7 -> 350 | E17: =D17+F17 -> 350 | G17: Mistake based on Rarity
C18: Spin | D18: =D28 -> 100 | E18: =D18+F18 -> 100 | G18: =G8 -> 7
C19: Loft | D19: ='DEFAULT CLUBS-COMMON'!D19 -> 35 | E19: =D19+F19 -> 35
C20: Recovery | D20: =D30 -> 108 | E20: =D20+F20 -> 108
C21: Durability | D21: =D11 -> 300 | E21: =D21+F21 -> 300
H22: . | K22: Randomizer | L22: =RANDBETWEEN(0,3) -> 2 | M22: Mechanical Misake | N22: 1
L23: SemiRough | M23: SemiRough | U23: ROLL AFTER COEFFICIENT
F24: UPGRADES | L24: =VLOOKUP(L23,RECOVERY!$AA$8:$AP$10,4,FALSE) -> 1.4 | M24: =VLOOKUP(M23,RECOVERY!$AA$27:$AP$29,4,FALSE) -> 0.65 | N24: -1.5 | O24: 0 | P24: 1.5 | R24: 1/-1 | T24: 0.1 | U24: 1.33 | V24: -1.23
B25: LEGENDARY | D25: Base Parameter | E25: Parameter | F25: =F15 -> 0/235 | G25: Base Rar Dist | H25: SHOT DISTANCE | I25: ACC. Coeff | J25: Shot Power Multiplyer | K25: ACC. DEVIATION | L25: REC. FOR ACC | M25: REC. FOR POWER | N25: TOP SPIN | O25: NO SPIN | P25: BACK SPIN | Q25: Deviation | R25: SIDE SPIN POWER | S25: Calculated Spin | T25: DEFAULT | U25: TOP SPIN | V25: BACK SPIN
B26: 5-Wood | C26: Power | D26: =D16-10 -> 250 | E26: =D26+F26 -> 250 | G26: =G16 -> 50 | H26: =$G$6+(E26/2)+$AB$6+(Z26/2)+$L$2 -> 220 | I26: =1-(E27/1000) -> 0.645 | J26: =ROUND(POWER(E26/100,0.5),3) -> 1.581 | K26: =(G28*J26*I26*N22) -> 7.138215 | L26: =1+(L24-1)*(1-E30/500) -> 1.3136 | M26: =M24+((1-M24)*0.5*E30/400) -> 0.69725 | N26: =(E29+(Q26*N24))/1.3 -> 23.461538 | O26: =(D29+(P26*O24))/1.3 -> 26.923077 | P26: =(E29+(Q26*P24))/1.3 -> 30.384615 | Q26: =3*(E28/100) -> 3 | R26: =E28*1*(VLOOKUP(B26,SPIN!$M$27:$N$40,2,FALSE)) -> 5000 | S26: =E28*2*3.14/60 -> 10.466667 | T26: =$S26*T24*8 -> 8.3733333 | U26: =$S26*U24*8 -> 111.36533 | V26: =$S26*V24*8 -> -102.992
C27: Accuracy | D27: =D17+5 -> 355 | E27: =D27+F27 -> 355 | G27: Mistake based on Rarity
C28: Spin | D28: =D48 -> 100 | E28: =D28+F28 -> 100 | G28: =G18 -> 7
C29: Loft | D29: ='DEFAULT CLUBS-COMMON'!D29 -> 35 | E29: =D29+F29 -> 35
C30: Recovery | D30: =D40 -> 108 | E30: =D30+F30 -> 108
C31: Durability | D31: =D21 -> 300 | E31: =D31+F31 -> 300
H32: . | K32: Randomizer | L32: =RANDBETWEEN(0,3) -> 3 | M32: Mechanical Misake | N32: 1
L33: SemiRough | M33: SemiRough | U33: ROLL AFTER COEFFICIENT
F34: UPGRADES | L34: =VLOOKUP(L33,RECOVERY!$AA$8:$AP$10,5,FALSE) -> 1.4 | M34: =VLOOKUP(M33,RECOVERY!$AA$27:$AP$29,5,FALSE) -> 0.65 | N34: -1.5 | O34: 0 | P34: 1.5 | R34: 1/-1 | T34: 0.1 | U34: 1.33 | V34: -1.23
B35: LEGENDARY | D35: Base Parameter | E35: Parameter | F35: =F25 -> 0/235 | G35: Base Rar Dist | H35: SHOT DISTANCE | I35: ACC. Coeff | J35: Shot Power Multiplyer | K35: ACC. DEVIATION | L35: REC. FOR ACC | M35: REC. FOR POWER | N35: TOP SPIN | O35: NO SPIN | P35: BACK SPIN | Q35: Deviation | R35: SIDE SPIN POWER | S35: Calculated Spin | T35: DEFAULT | U35: TOP SPIN | V35: BACK SPIN
B36: 7-Wood | C36: Power | D36: =D26-10 -> 240 | E36: =D36+F36 -> 240 | G36: =G26 -> 50 | H36: =$G$6+(E36/2)+$AB$6+(Z36/2)+$L$2 -> 215 | I36: =1-(E37/1000) -> 0.645 | J36: =ROUND(POWER(E36/100,0.5),3) -> 1.549 | K36: =(G38*J36*I36*N32) -> 6.993735 | L36: =1+(L34-1)*(1-E40/500) -> 1.3136 | M36: =M34+((1-M34)*0.5*E40/400) -> 0.69725 | N36: =(E39+(Q36*N34))/1.3 -> 23.323077 | O36: =(D39+(P36*O34))/1.3 -> 26.923077 | P36: =(E39+(Q36*P34))/1.3 -> 30.523077 | Q36: =3*(E38/100) -> 3.12 | R36: =E38*1*(VLOOKUP(B36,SPIN!$M$27:$N$40,2,FALSE)) -> 5200 | S36: =E38*2*3.14/60 -> 10.885333 | T36: =$S36*T34*8 -> 8.7082667 | U36: =$S36*U34*8 -> 115.81995 | V36: =$S36*V34*8 -> -107.11168
C37: Accuracy | D37: =D27 -> 355 | E37: =D37+F37 -> 355 | G37: Mistake based on Rarity
C38: Spin | D38: =D48+4 -> 104 | E38: =D38+F38 -> 104 | G38: =G28 -> 7
C39: Loft | D39: ='DEFAULT CLUBS-COMMON'!D39 -> 35 | E39: =D39+F39 -> 35
C40: Recovery | D40: =D50 -> 108 | E40: =D40+F40 -> 108
C41: Durability | D41: =D31 -> 300 | E41: =D41+F41 -> 300
...

Sheet DEFAULT CLUBS-SUPREME
H2: . | K2: Randomizer | L2: =RANDBETWEEN(0,3) -> 3 | M2: Mechanical Misake | N2: 1 | Z2: CHARCTER | AC2: UPGRADES
L3: SemiRough | M3: SemiRough | U3: ROLL AFTER COEFFICIENT
F4: UPGRADES | L4: =VLOOKUP(L3,RECOVERY!$AA$8:$AP$10,2,FALSE) -> 1.4 | M4: =VLOOKUP(M3,RECOVERY!$AA$27:$AP$29,2,FALSE) -> 0.65 | N4: -1.5 | O4: 0 | P4: 1.5 | R4: 1/-1 | T4: 0.1 | U4: 1.33 | V4: -1.23
B5: SUPREME | D5: Base Parameter | E5: Parameter | F5: =SUM(F6:F11)&"/325" -> 0/325 | G5: Base Rar Dist | H5: SHOT DISTANCE | I5: ACC. Coeff | J5: Shot Power Multiplyer | K5: ACC. DEVIATION | L5: REC. FOR ACC | M5: REC. FOR POWER | N5: TOP SPIN | O5: NO SPIN | P5: BACK SPIN | Q5: Deviation | R5: SIDE SPIN | S5: Calculated Spin | T5: DEFAULT | U5: TOP SPIN | V5: BACK SPIN | Z5: SUPREME | AA5: Base Parameter | AB5: Parameter | AC5: =SUM(AC6:AC9)&"/25" -> 0/25 | AD5: Base Rar Dist
B6: Driver | C6: Power | D6: 300 | E6: =D6+F6 -> 300 | G6: 55 | H6: =$G$6+(E6/2)+$AD$6+(AB6/2)+$L$2 -> 258 | I6: =1-(E7/1000) -> 0.6 | J6: =ROUND(POWER(E6/100,0.5),3) -> 1.732 | K6: =(G8*J6*I6*N2) -> 5.196 | L6: =1+(L4-1)*(1-E10/500) -> 1.2784 | M6: =M4+((1-M4)*0.5*E10/400) -> 0.7165 | N6: =(E9+(Q6*N4))/1.3 -> 23.461538 | O6: =(D9+(P6*O4))/1.3 -> 26.923077 | P6: =(E9+(Q6*P4))/1.3 -> 30.384615 | Q6: =3*(E8/100) -> 3 | R6: =E8*1*(VLOOKUP(B6,SPIN!$M$27:$N$40,2,FALSE)) -> 4000 | S6: =E8*2*3.14/60 -> 10.466667 | T6: =$S6*T4*8 -> 8.3733333 | U6: =$S6*U4*8 -> 111.36533 | V6: =$S6*V4*8 -> -102.992 | Z6: STRENGTH | AA6: 40 | AB6: =AA6+AC6 -> 40 | AD6: 30
C7: Accuracy | D7: 400 | E7: =D7+F7 -> 400 | G7: Mistake based on Rarity | H7: . | Z7: CLUB CONTROL | AA7: 50 | AB7: =AA7+AC7 -> 50
C8: Spin | D8: =D18-15 -> 100 | E8: =D8+F8 -> 100 | G8: 5 | Z8: STAMINA | AA8: 150 | AB8: =AA8+AC8 -> 150
C9: Loft | D9: ='DEFAULT CLUBS-COMMON'!D9 -> 35 | E9: =D9+F9 -> 35 | Z9: STAMINA REG | AA9: 5 | AB9: =AA9+AC9 -> 5
C10: Recovery | D10: =D20-6 -> 152 | E10: =D10+F10 -> 152
C11: Durability | D11: 350 | E11: =D11+F11 -> 350
H12: . | K12: Randomizer | L12: =RANDBETWEEN(0,3) -> 2 | M12: Mechanical Misake | N12: 1
L13: SemiRough | M13: SemiRough | U13: ROLL AFTER COEFFICIENT
F14: UPGRADES | L14: =VLOOKUP(L13,RECOVERY!$AA$8:$AP$10,3,FALSE) -> 1.4 | M14: =VLOOKUP(M13,RECOVERY!$AA$27:$AP$29,3,FALSE) -> 0.65 | N14: -1.5 | O14: 0 | P14: 1.5 | R14: 1/-1 | T14: 0.1 | U14: 1.33 | V14: -1.23
B15: SUPREME | D15: Base Parameter | E15: Parameter | F15: =SUM(F16:F21)&"/325" -> 0/325 | G15: Base Rar Dist | H15: SHOT DISTANCE | I15: ACC. Coeff | J15: Shot Power Multiplyer | K15: ACC. DEVIATION | L15: REC. FOR ACC | M15: REC. FOR POWER | N15: TOP SPIN | O15: NO SPIN | P15: BACK SPIN | Q15: Deviation | R15: SIDE SPIN | S15: Calculated Spin | T15: DEFAULT | U15: TOP SPIN | V15: BACK SPIN
B16: 3-Wood | C16: Power | D16: =D6-10 -> 290 | E16: =D16+F16 -> 290 | G16: 55 | H16: =$G$6+(E16/2)+$AD$6+(AB16/2)+$L$2 -> 233 | I16: =1-(E17/1000) -> 0.6 | J16: =ROUND(POWER(E16/100,0.5),3) -> 1.703 | K16: =(G18*J16*I16*N12) -> 5.109 | L16: =1+(L14-1)*(1-E20/500) -> 1.2736 | M16: =M14+((1-M14)*0.5*E20/400) -> 0.719125 | N16: =(E19+(Q16*N14))/1.3 -> 22.942308 | O16: =(D19+(P16*O14))/1.3 -> 26.923077 | P16: =(E19+(Q16*P14))/1.3 -> 30.903846 | Q16: =3*(E18/100) -> 3.45 | R16: =E18*1*(VLOOKUP(B16,SPIN!$M$27:$N$40,2,FALSE)) -> 5750 | S16: =E18*2*3.14/60 -> 12.036667 | T16: =$S16*T14*8 -> 9.6293333 | U16: =$S16*U14*8 -> 128.07013 | V16: =$S16*V14*8 -> -118.4408
C17: Accuracy | D17: =D7 -> 400 | E17: =D17+F17 -> 400 | G17: Mistake based on Rarity
C18: Spin | D18: =D28 -> 115 | E18: =D18+F18 -> 115 | G18: 5
C19: Loft | D19: ='DEFAULT CLUBS-COMMON'!D19 -> 35 | E19: =D19+F19 -> 35
C20: Recovery | D20: =D30 -> 158 | E20: =D20+F20 -> 158
C21: Durability | D21: =D11 -> 350 | E21: =D21+F21 -> 350
H22: . | K22: Randomizer | L22: =RANDBETWEEN(0,3) -> 3 | M22: Mechanical Misake | N22: 1
L23: SemiRough | M23: SemiRough | U23: ROLL AFTER COEFFICIENT
F24: UPGRADES | L24: =VLOOKUP(L23,RECOVERY!$AA$8:$AP$10,4,FALSE) -> 1.4 | M24: =VLOOKUP(M23,RECOVERY!$AA$27:$AP$29,4,FALSE) -> 0.65 | N24: -1.5 | O24: 0 | P24: 1.5 | R24: 1/-1 | T24: 0.1 | U24: 1.33 | V24: -1.23
B25: SUPREME | D25: Base Parameter | E25: Parameter | F25: =SUM(F26:F31)&"/325" -> 0/325 | G25: Base Rar Dist | H25: SHOT DISTANCE | I25: ACC. Coeff | J25: Shot Power Multiplyer | K25: ACC. DEVIATION | L25: REC. FOR ACC | M25: REC. FOR POWER | N25: TOP SPIN | O25: NO SPIN | P25: BACK SPIN | Q25: Deviation | R25: SIDE SPIN | S25: Calculated Spin | T25: DEFAULT | U25: TOP SPIN | V25: BACK SPIN
B26: 5-Wood | C26: Power | D26: =D16-10 -> 280 | E26: =D26+F26 -> 280 | G26: 55 | H26: =$G$6+(E26/2)+$AD$6+(AB26/2)+$L$2 -> 228 | I26: =1-(E27/1000) -> 0.595 | J26: =ROUND(POWER(E26/100,0.5),3) -> 1.673 | K26: =(G28*J26*I26*N22) -> 4.977175 | L26: =1+(L24-1)*(1-E30/500) -> 1.2736 | M26: =M24+((1-M24)*0.5*E30/400) -> 0.719125 | N26: =(E29+(Q26*N24))/1.3 -> 22.942308 | O26: =(D29+(P26*O24))/1.3 -> 26.923077 | P26: =(E29+(Q26*P24))/1.3 -> 30.903846 | Q26: =3*(E28/100) -> 3.45 | R26: =E28*1*(VLOOKUP(B26,SPIN!$M$27:$N$40,2,FALSE)) -> 5750 | S26: =E28*2*3.14/60 -> 12.036667 | T26: =$S26*T24*8 -> 9.6293333 | U26: =$S26*U24*8 -> 128.07013 | V26: =$S26*V24*8 -> -118.4408
C27: Accuracy | D27: =D17+5 -> 405 | E27: =D27+F27 -> 405 | G27: Mistake based on Rarity
C28: Spin | D28: =D48 -> 115 | E28: =D28+F28 -> 115 | G28: 5
C29: Loft | D29: ='DEFAULT CLUBS-COMMON'!D29 -> 35 | E29: =D29+F29 -> 35
C30: Recovery | D30: =D40 -> 158 | E30: =D30+F30 -> 158
C31: Durability | D31: =D21 -> 350 | E31: =D31+F31 -> 350
H32: . | K32: Randomizer | L32: =RANDBETWEEN(0,3) -> 3 | M32: Mechanical Misake | N32: 1
L33: SemiRough | M33: SemiRough | U33: ROLL AFTER COEFFICIENT
F34: UPGRADES | L34: =VLOOKUP(L33,RECOVERY!$AA$8:$AP$10,5,FALSE) -> 1.4 | M34: =VLOOKUP(M33,RECOVERY!$AA$27:$AP$29,5,FALSE) -> 0.65 | N34: -1.5 | O34: 0 | P34: 1.5 | R34: 1/-1 | T34: 0.1 | U34: 1.33 | V34: -1.23
B35: SUPREME | D35: Base Parameter | E35: Parameter | F35: =SUM(F36:F41)&"/325" -> 0/325 | G35: Base Rar Dist | H35: SHOT DISTANCE | I35: ACC. Coeff | J35: Shot Power Multiplyer | K35: ACC. DEVIATION | L35: REC. FOR ACC | M35: REC. FOR POWER | N35: TOP SPIN | O35: NO SPIN | P35: BACK SPIN | Q35: Deviation | R35: SIDE SPIN | S35: Calculated Spin | T35: DEFAULT | U35: TOP SPIN | V35: BACK SPIN
B36: 7-Wood | C36: Power | D36: =D26-10 -> 270 | E36: =D36+F36 -> 270 | G36: 55 | H36: =$G$6+(E36/2)+$AD$6+(AB36/2)+$L$2 -> 223 | I36: =1-(E37/1000) -> 0.595 | J36: =ROUND(POWER(E36/100,0.5),3) -> 1.643 | K36: =(G38*J36*I36*N32) -> 4.887925 | L36: =1+(L34-1)*(1-E40/500) -> 1.2736 | M36: =M34+((1-M34)*0.5*E40/400) -> 0.719125 | N36: =(E39+(Q36*N34))/1.3 -> 22.803846 | O36: =(D39+(P36*O34))/1.3 -> 26.923077 | P36: =(E39+(Q36*P34))/1.3 -> 31.042308 | Q36: =3*(E38/100) -> 3.57 | R36: =E38*1*(VLOOKUP(B36,SPIN!$M$27:$N$40,2,FALSE)) -> 5950 | S36: =E38*2*3.14/60 -> 12.455333 | T36: =$S36*T34*8 -> 9.9642667 | U36: =$S36*U34*8 -> 132.52475 | V36: =$S36*V34*8 -> -122.56048
C37: Accuracy | D37: =D27 -> 405 | E37: =D37+F37 -> 405 | G37: Mistake based on Rarity
C38: Spin | D38: =D48+4 -> 119 | E38: =D38+F38 -> 119 | G38: 5
C39: Loft | D39: ='DEFAULT CLUBS-COMMON'!D39 -> 35 | E39: =D39+F39 -> 35
C40: Recovery | D40: =D50 -> 158 | E40: =D40+F40 -> 158
C41: Durability | D41: =D31 -> 350 | E41: =D41+F41 -> 350
...

Sheet CLUB CONTROL
I1: Club Control of a Character
B2: 325 | I2: Directly affects the size of outer circles
B3: Parameter | G3: %
A4: Chara | B4: =C4+$B$2 -> 525 | C4: 200 | F4: ZONE SIZE | G4: =15+(85*SQRT((B4-10)/515)) -> 100
I5: SIZE OF THE OUTER CIRCLES
I7: Size: (30+(70*square root((A-10)/515)))*Club Control Penalty Based on Terrain
I8: A: Club Control Parameter
I11: Club Control penalty based on type of terrain and type of the club
J12: Fairway | K12: SemiRough | L12: Rough | M12: Bunker | N12: Fringe
I13: driver | J13: 0.65 | K13: 0.65 | L13: 0.45 | M13: 0.25 | N13: 0.75
I14: 3-Wood | J14: 1 | K14: 0.65 | L14: 0.45 | M14: 0.25 | N14: 0.75
I15: 5-Wood | J15: 1 | K15: 0.65 | L15: 0.45 | M15: 0.25 | N15: 0.75
I16: 7-Wood | J16: 1 | K16: 0.65 | L16: 0.45 | M16: 0.25 | N16: 0.75
I17: 3-Iron | J17: 1 | K17: 0.65 | L17: 0.45 | M17: 0.25 | N17: 0.75
I18: 4-Iron | J18: 1 | K18: 0.65 | L18: 0.45 | M18: 0.25 | N18: 0.75
I19: 5-Iron | J19: 1 | K19: 0.75 | L19: 0.55 | M19: 0.35 | N19: 0.75
I20: 6-Iron | J20: 1 | K20: 0.75 | L20: 0.55 | M20: 0.35 | N20: 0.75
I21: 7-Iron | J21: 1 | K21: 0.75 | L21: 0.55 | M21: 0.35 | N21: 0.75
I22: 8-Iron | J22: 1 | K22: 0.75 | L22: 0.55 | M22: 0.35 | N22: 0.95
I23: 9-Iron | J23: 1 | K23: 0.75 | L23: 0.55 | M23: 0.35 | N23: 0.95
I24: Pitching Wedge | J24: 1 | K24: 0.85 | L24: 0.65 | M24: 0.55 | N24: 0.95
... I26: Sand Wedge | J26: 1 | K26: 0.85 | L26: 0.65 | M26: 0.65 | N26: 0.95
I27: Putter | J27: - | K27: - | L27: - | M27: - | N27: -

Sheet RECOVERY
O2: RECOVERY of the Club
O3: Affects how easy it is to make shots from the rough and bunker
A4: Accuracy penalty based on type of terrain and type of the club | H4: Power terrain multiplier based on type of terrain and type of the club | O4: As Recovery increases, the penalty that terrain inflicts on other parameters is decreased
C5: SemiRough | D5: Rough | E5: Bunker | J5: SemiRough | K5: Rough | L5: Bunker
A6: driver | C6: 1.4 | D6: 2 | E6: 2.5 | H6: driver | J6: 0.65 | K6: 0.45 | L6: 0.25
A7: 3-Wood | C7: 1.4 | D7: 2 | E7: 2.5 | H7: 3-Wood | J7: 0.65 | K7: 0.45 | L7: 0.25 | O7: RECOVERY FOR ACCURACY | U7: Accuracy penalty based on type of terrain and type of the club | AB7: driver | AC7: 3-Wood | AD7: 5-Wood | AE7: 7-Wood | AF7: 3-Iron | AG7: 4-Iron | AH7: 5-Iron | AI7: 6-Iron | AJ7: 7-Iron | AK7: 8-Iron | AL7: 9-Iron | AM7: Pitching Wedge | AN7: Approach Wedge | AO7: Sand Wedge | AP7: Putter
A8: 5-Wood | C8: 1.4 | D8: 2 | E8: 2.5 | H8: 5-Wood | J8: 0.65 | K8: 0.45 | L8: 0.25 | W8: SemiRough | X8: Rough | Y8: Bunker | AA8: Rough | AB8: 2 | AC8: 2 | AD8: 2 | AE8: 2 | AF8: 1.8 | AG8: 1.8 | AH8: 1.6 | AI8: 1.6 | AJ8: 1.6 | AK8: 1.45 | AL8: 1.45 | AM8: 1.4 | AN8: 1.4 | AO8: 1.4 | AP8: -
A9: 7-Wood | C9: 1.4 | D9: 2 | E9: 2.5 | H9: 7-Wood | J9: 0.65 | K9: 0.45 | L9: 0.25 | O9: RECOVERY FOR ACCURACY DEVIATION: 1+(A-1)*(1-B/500) | U9: driver | W9: 1.4 | X9: 2 | Y9: 2.5 | AA9: SemiRough | AB9: 1.4 | AC9: 1.4 | AD9: 1.4 | AE9: 1.4 | AF9: 1.3 | AG9: 1.3 | AH9: 1.25 | AI9: 1.25 | AJ9: 1.25 | AK9: 1.2 | AL9: 1.2 | AM9: 1.15 | AN9: 1.15 | AO9: 1.15 | AP9: -
A10: 3-Iron | C10: 1.3 | D10: 1.8 | E10: 2.2 | H10: 3-Iron | J10: 0.65 | K10: 0.45 | L10: 0.25 | O10: A: Accuracy penalty based on type of terrain and type of the club | U10: 3-Wood | W10: 1.4 | X10: 2 | Y10: 2.5 | AA10: Bunker | AB10: 2.5 | AC10: 2.5 | AD10: 2.5 | AE10: 2.5 | AF10: 2.2 | AG10: 2.2 | AH10: 2 | AI10: 2 | AJ10: 2 | AK10: 1.7 | AL10: 1.7 | AM10: 1.5 | AN10: 1.5 | AO10: 1.3 | AP10: -
A11: 4-Iron | C11: 1.3 | D11: 1.8 | E11: 2.2 | H11: 4-Iron | J11: 0.65 | K11: 0.45 | L11: 0.25 | O11: B: Club Recovery Parameter | U11: 5-Wood | W11: 1.4 | X11: 2 | Y11: 2.5
A12: 5-Iron | C12: 1.25 | D12: 1.6 | E12: 2 | H12: 5-Iron | J12: 0.75 | K12: 0.55 | L12: 0.35 | U12: 7-Wood | W12: 1.4 | X12: 2 | Y12: 2.5
A13: 6-Iron | C13: 1.25 | D13: 1.6 | E13: 2 | H13: 6-Iron | J13: 0.75 | K13: 0.55 | L13: 0.35 | U13: 3-Iron | W13: 1.3 | X13: 1.8 | Y13: 2.2
A14: 7-Iron | C14: 1.25 | D14: 1.6 | E14: 2 | H14: 7-Iron | J14: 0.75 | K14: 0.55 | L14: 0.35 | U14: 4-Iron | W14: 1.3 | X14: 1.8 | Y14: 2.2
A15: 8-Iron | C15: 1.2 | D15: 1.45 | E15: 1.7 | H15: 8-Iron | J15: 0.75 | K15: 0.55 | L15: 0.35 | U15: 5-Iron | W15: 1.25 | X15: 1.6 | Y15: 2
A16: 9-Iron | C16: 1.2 | D16: 1.45 | E16: 1.7 | H16: 9-Iron | J16: 0.75 | K16: 0.55 | L16: 0.35 | U16: 6-Iron | W16: 1.25 | X16: 1.6 | Y16: 2
A17: Pitching Wedge | C17: 1.15 | D17: 1.4 | E17: 1.5 | H17: Pitching Wedge | J17: 0.85 | K17: 0.65 | L17: 0.55 | U17: 7-Iron | W17: 1.25 | X17: 1.6 | Y17: 2
A18: Approach Wedge | C18: 1.15 | D18: 1.4 | E18: 1.5 | H18: Approach Wedge | J18: 0.85 | K18: 0.65 | L18: 0.55 | U18: 8-Iron | W18: 1.2 | X18: 1.45 | Y18: 1.7
A19: Sand Wedge | C19: 1.15 | D19: 1.4 | E19: 1.3 | H19: Sand Wedge | J19: 0.85 | K19: 0.65 | L19: 0.65 | U19: 9-Iron | W19: 1.2 | X19: 1.45 | Y19: 1.7
U20: Pitching Wedge | W20: 1.15 | X20: 1.4 | Y20: 1.5
U21: Approach Wedge | W21: 1.15 | X21: 1.4 | Y21: 1.5
B22: 0 | U22: Sand Wedge | W22: 1.15 | X22: 1.4 | Y22: 1.3
B23: COMMON | E23: SemiRough | F23: Rough | G23: Bunker | I23: SemiRough | J23: Rough | K23: Bunker | U23: Putter
A24: driver | B24: =C24+$B$22 -> 4 | C24: 4 | E24: =1+(C6-1)*(1-$B24/500) -> 1.3968 | F24: =1+(D6-1)*(1-$B24/500) -> 1.992 | G24: =1+(E6-1)*(1-$B24/500) -> 2.488 | H24: driver | I24: =J6+((1-J6)*0.5*$B24/400) -> 0.65175 | J24: =K6+((1-K6)*0.5*$B24/400) -> 0.45275 | K24: =L6+((1-L6)*0.5*$B24/400) -> 0.25375
A25: 3-Wood | B25: =C25+$B$22 -> 4 | C25: 4 | E25: =1+(C7-1)*(1-$B25/500) -> 1.3968 | F25: =1+(D7-1)*(1-$B25/500) -> 1.992 | G25: =1+(E7-1)*(1-$B25/500) -> 2.488 | H25: 3-Wood | I25: =J7+((1-J7)*0.5*$B25/400) -> 0.65175 | J25: =K7+((1-K7)*0.5*$B25/400) -> 0.45275 | K25: =L7+((1-L7)*0.5*$B25/400) -> 0.25375 | O25: RECOVERY FOR POWER | U25: Power terrain multiplier based on type of terrain and type of the club
A26: 5-Wood | B26: =C26+$B$22 -> 4 | C26: 4 | E26: =1+(C8-1)*(1-$B26/500) -> 1.3968 | F26: =1+(D8-1)*(1-$B26/500) -> 1.992 | G26: =1+(E8-1)*(1-$B26/500) -> 2.488 | H26: 5-Wood | I26: =J8+((1-J8)*0.5*$B26/400) -> 0.65175 | J26: =K8+((1-K8)*0.5*$B26/400) -> 0.45275 | K26: =L8+((1-L8)*0.5*$B26/400) -> 0.25375 | W26: SemiRough | X26: Rough | Y26: Bunker | AB26: driver | AC26: 3-Wood | AD26: 5-Wood | AE26: 7-Wood | AF26: 3-Iron | AG26: 4-Iron | AH26: 5-Iron | AI26: 6-Iron | AJ26: 7-Iron | AK26: 8-Iron | AL26: 9-Iron | AM26: Pitching Wedge | AN26: Approach Wedge | AO26: Sand Wedge | AP26: Putter
A27: 7-Wood | B27: =C27+$B$22 -> 4 | C27: 4 | E27: =1+(C9-1)*(1-$B27/500) -> 1.3968 | F27: =1+(D9-1)*(1-$B27/500) -> 1.992 | G27: =1+(E9-1)*(1-$B27/500) -> 2.488 | H27: 7-Wood | I27: =J9+((1-J9)*0.5*$B27/400) -> 0.65175 | J27: =K9+((1-K9)*0.5*$B27/400) -> 0.45275 | K27: =L9+((1-L9)*0.5*$B27/400) -> 0.25375 | O27: RECOVERY FOR POWER DEVIATION: C+((1-C)*0.5*D/400) | U27: driver | W27: 0.65 | X27: 0.45 | Y27: 0.25 | AA27: Rough | AB27: 0.45 | AC27: 0.45 | AD27: 0.45 | AE27: 0.45 | AF27: 0.45 | AG27: 0.45 | AH27: 0.55 | AI27: 0.55 | AJ27: 0.55 | AK27: 0.55 | AL27: 0.55 | AM27: 0.65 | AN27: 0.65 | AO27: 0.65 | AP27: -
A28: 3-Iron | B28: =C28+$B$22 -> 4 | C28: 4 | E28: =1+(C10-1)*(1-$B28/500) -> 1.2976 | F28: =1+(D10-1)*(1-$B28/500) -> 1.7936 | G28: =1+(E10-1)*(1-$B28/500) -> 2.1904 | H28: 3-Iron | I28: =J10+((1-J10)*0.5*$B28/400) -> 0.65175 | J28: =K10+((1-K10)*0.5*$B28/400) -> 0.45275 | K28: =L10+((1-L10)*0.5*$B28/400) -> 0.25375 | O28: C: Power terrain multiplier based on type of terrain and type of the club | U28: 3-Wood | W28: 0.65 | X28: 0.45 | Y28: 0.25 | AA28: SemiRough | AB28: 0.65 | AC28: 0.65 | AD28: 0.65 | AE28: 0.65 | AF28: 0.65 | AG28: 0.65 | AH28: 0.75 | AI28: 0.75 | AJ28: 0.75 | AK28: 0.75 | AL28: 0.75 | AM28: 0.85 | AN28: 0.85 | AO28: 0.85 | AP28: -
A29: 4-Iron | B29: =C29+$B$22 -> 4 | C29: 4 | E29: =1+(C11-1)*(1-$B29/500) -> 1.2976 | F29: =1+(D11-1)*(1-$B29/500) -> 1.7936 | G29: =1+(E11-1)*(1-$B29/500) -> 2.1904 | H29: 4-Iron | I29: =J11+((1-J11)*0.5*$B29/400) -> 0.65175 | J29: =K11+((1-K11)*0.5*$B29/400) -> 0.45275 | K29: =L11+((1-L11)*0.5*$B29/400) -> 0.25375 | O29: D: Club Recovery Parameter | U29: 5-Wood | W29: 0.65 | X29: 0.45 | Y29: 0.25 | AA29: Bunker | AB29: 0.25 | AC29: 0.25 | AD29: 0.25 | AE29: 0.25 | AF29: 0.25 | AG29: 0.25 | AH29: 0.35 | AI29: 0.35 | AJ29: 0.35 | AK29: 0.35 | AL29: 0.35 | AM29: 0.55 | AN29: 0.55 | AO29: 0.65 | AP29: -
A30: 5-Iron | B30: =C30+$B$22 -> 4 | C30: 4 | E30: =1+(C12-1)*(1-$B30/500) -> 1.248 | F30: =1+(D12-1)*(1-$B30/500) -> 1.5952 | G30: =1+(E12-1)*(1-$B30/500) -> 1.992 | H30: 5-Iron | I30: =J12+((1-J12)*0.5*$B30/400) -> 0.75125 | J30: =K12+((1-K12)*0.5*$B30/400) -> 0.55225 | K30: =L12+((1-L12)*0.5*$B30/400) -> 0.35325 | U30: 7-Wood | W30: 0.65 | X30: 0.45 | Y30: 0.25
A31: 6-Iron | B31: =C31+$B$22 -> 4 | C31: 4 | E31: =1+(C13-1)*(1-$B31/500) -> 1.248 | F31: =1+(D13-1)*(1-$B31/500) -> 1.5952 | G31: =1+(E13-1)*(1-$B31/500) -> 1.992 | H31: 6-Iron | I31: =J13+((1-J13)*0.5*$B31/400) -> 0.75125 | J31: =K13+((1-K13)*0.5*$B31/400) -> 0.55225 | K31: =L13+((1-L13)*0.5*$B31/400) -> 0.35325 | U31: 3-Iron | W31: 0.65 | X31: 0.45 | Y31: 0.25
A32: 7-Iron | B32: =C32+$B$22 -> 4 | C32: 4 | E32: =1+(C14-1)*(1-$B32/500) -> 1.248 | F32: =1+(D14-1)*(1-$B32/500) -> 1.5952 | G32: =1+(E14-1)*(1-$B32/500) -> 1.992 | H32: 7-Iron | I32: =J14+((1-J14)*0.5*$B32/400) -> 0.75125 | J32: =K14+((1-K14)*0.5*$B32/400) -> 0.55225 | K32: =L14+((1-L14)*0.5*$B32/400) -> 0.35325 | U32: 4-Iron | W32: 0.65 | X32: 0.45 | Y32: 0.25
A33: 8-Iron | B33: =C33+$B$22 -> 15 | C33: 15 | E33: =1+(C15-1)*(1-$B33/500) -> 1.194 | F33: =1+(D15-1)*(1-$B33/500) -> 1.4365 | G33: =1+(E15-1)*(1-$B33/500) -> 1.679 | H33: 8-Iron | I33: =J15+((1-J15)*0.5*$B33/400) -> 0.7546875 | J33: =K15+((1-K15)*0.5*$B33/400) -> 0.5584375 | K33: =L15+((1-L15)*0.5*$B33/400) -> 0.3621875 | U33: 5-Iron | W33: 0.75 | X33: 0.55 | Y33: 0.35
A34: 9-Iron | B34: =C34+$B$22 -> 15 | C34: 15 | E34: =1+(C16-1)*(1-$B34/500) -> 1.194 | F34: =1+(D16-1)*(1-$B34/500) -> 1.4365 | G34: =1+(E16-1)*(1-$B34/500) -> 1.679 | H34: 9-Iron | I34: =J16+((1-J16)*0.5*$B34/400) -> 0.7546875 | J34: =K16+((1-K16)*0.5*$B34/400) -> 0.5584375 | K34: =L16+((1-L16)*0.5*$B34/400) -> 0.3621875 | U34: 6-Iron | W34: 0.75 | X34: 0.55 | Y34: 0.35
A35: Pitching Wedge | B35: =C35+$B$22 -> 15 | C35: 15 | E35: =1+(C17-1)*(1-$B35/500) -> 1.1455 | F35: =1+(D17-1)*(1-$B35/500) -> 1.388 | G35: =1+(E17-1)*(1-$B35/500) -> 1.485 | H35: Pitching Wedge | I35: =J17+((1-J17)*0.5*$B35/400) -> 0.8528125 | J35: =K17+((1-K17)*0.5*$B35/400) -> 0.6565625 | K35: =L17+((1-L17)*0.5*$B35/400) -> 0.5584375 | U35: 7-Iron | W35: 0.75 | X35: 0.55 | Y35: 0.35
A36: Approach Wedge | B36: =C36+$B$22 -> 15 | C36: 15 | E36: =1+(C18-1)*(1-$B36/500) -> 1.1455 | F36: =1+(D18-1)*(1-$B36/500) -> 1.388 | G36: =1+(E18-1)*(1-$B36/500) -> 1.485 | H36: Approach Wedge | I36: =J18+((1-J18)*0.5*$B36/400) -> 0.8528125 | J36: =K18+((1-K18)*0.5*$B36/400) -> 0.6565625 | K36: =L18+((1-L18)*0.5*$B36/400) -> 0.5584375 | U36: 8-Iron | W36: 0.75 | X36: 0.55 | Y36: 0.35
A37: Sand Wedge | B37: =C37+$B$22 -> 15 | C37: 15 | E37: =1+(C19-1)*(1-$B37/500) -> 1.1455 | F37: =1+(D19-1)*(1-$B37/500) -> 1.388 | G37: =1+(E19-1)*(1-$B37/500) -> 1.291 | H37: Sand Wedge | I37: =J19+((1-J19)*0.5*$B37/400) -> 0.8528125 | J37: =K19+((1-K19)*0.5*$B37/400) -> 0.6565625 | K37: =L19+((1-L19)*0.5*$B37/400) -> 0.6565625 | U37: 9-Iron | W37: 0.75 | X37: 0.55 | Y37: 0.35
A38: Putter | B38: =C38+$B$22 -> 1 | C38: 1 | E38: =1+(C20-1)*(1-$B38/500) -> 0.002 | F38: =1+(D20-1)*(1-$B38/500) -> 0.002 | G38: =1+(E20-1)*(1-$B38/500) -> 0.002 | H38: Putter | U38: Pitching Wedge | W38: 0.85 | X38: 0.65 | Y38: 0.55
U39: Approach Wedge | W39: 0.85 | X39: 0.65 | Y39: 0.55
U40: Sand Wedge | W40: 0.85 | X40: 0.65 | Y40: 0.65
D43: 27 | E43: =$D43*E24 -> 37.7136 | F43: =$D43*F24 -> 53.784 | G43: =$D43*G24 -> 67.176 | H43: 265 | I43: =$H43*I24 -> 172.71375 | J43: =$H43*J24 -> 119.97875 | K43: =$H43*K24 -> 67.24375
...

Sheet SPIN
A1: .
B2: 400 | E2: Natural Loft | G2: Deviation | H2: Lower point | I2: Middle | J2: Higher Point | M2: SPIN of the Club
B3: COMMON | H3: =1.5 -> 1.5 | I3: 0 | J3: -1.5 | M3: Affects the maximum amount of angle players can hit the ball with
A4: driver | B4: 55 | C4: 1 | E4: 35 | G4: =3*(B4/100) -> 1.65 | H4: =($E4+($G4*H$3))/1.3 -> 28.826923 | I4: =($E4+($G4*I$3))/1.3 -> 26.923077 | J4: =($E4+($G4*J$3))/1.3 -> 25.019231 | M4: to add to the Natural Loft of the club
A5: 3-Wood | B5: 55 | C5: 1 | E5: 35 | G5: =3*(B5/100) -> 1.65 | H5: =($E5+($G5*H$3))/1.3 -> 28.826923 | I5: =($E5+($G5*I$3))/1.3 -> 26.923077 | J5: =($E5+($G5*J$3))/1.3 -> 25.019231
A6: 5-Wood | B6: 55 | C6: 1 | E6: 35 | G6: =3*(B6/100) -> 1.65 | H6: =($E6+($G6*H$3))/1.3 -> 28.826923 | I6: =($E6+($G6*I$3))/1.3 -> 26.923077 | J6: =($E6+($G6*J$3))/1.3 -> 25.019231
